Workbook

Sheet Summary
A1: Teams from division that make playoffs | B1: Total Points to Playoffs
A2: 0 | B2: ='14.0'!T44 -> 1649
A3: 1 | B3: ='14.1'!T44 -> 1649
A4: 2 | B4: ='14.2'!T44 -> 1649
A5: 3 | B5: ='14.3 - model of cur system'!T44 -> 2237
A6: 4 | B6: ='14.4'!T44 -> 1647

Sheet 14.0
A1: Team | B1: i | C1: mi | D1: ai | E1: ci | F1: pi | G1: ti - current system | H1: d1i | I1: d2i | J1: d1i+d2i | K1: (ai+mi)*(d1i+d2i) | L1: (ci+pi)* (d1i+d2i) | M1: mi*d1i | N1: ai*d1i | O1: ci*d1i | P1: pi*d1i | Q1: d1i*ti*mi | R1: d2i*ti*mi | S1: d1i*ti*ai | T1: d2i*ti*ai | U1: d1i*ti*ci | V1: d2i*ti*ci | W1: d1i*ti*pi | X1: d2i*ti*pi
A2: Carolina Hurricanes | B2: 1 | C2: 1 | D2: 0 | E2: 0 | F2: 0 | G2: 83 | H2: 0 | I2: 0 | J2: =H2+I2 -> 0 | K2: =(C2+D2)*(H2+I2) -> 0 | L2: =(E2+F2)*(H2+I2) -> 0 | M2: =C2*H2 -> 0 | N2: =D2*H2 -> 0 | O2: =E2*H2 -> 0 | P2: =F2*H2 -> 0 | Q2: =H2*G2*C2 -> 0 | R2: =I2*G2*C2 -> 0 | S2: =H2*G2*D2 -> 0 | T2: =I2*G2*D2 -> 0 | U2: =H2*G2*E2 -> 0 | V2: =I2*G2*E2 -> 0 | W2: =H2*G2*F2 -> 0 | X2: =I2*G2*F2 -> 0
A3: Columbus Blue Jackets | B3: 2 | C3: 1 | D3: 0 | E3: 0 | F3: 0 | G3: 93 | H3: 0 | I3: 1 | J3: =H3+I3 -> 1 | K3: =(C3+D3)*(H3+I3) -> 1 | L3: =(E3+F3)*(H3+I3) -> 0 | M3: =C3*H3 -> 0 | N3: =D3*H3 -> 0 | O3: =E3*H3 -> 0 | P3: =F3*H3 -> 0 | Q3: =H3*G3*C3 -> 0 | R3: =I3*G3*C3 -> 93 | S3: =H3*G3*D3 -> 0 | T3: =I3*G3*D3 -> 0 | U3: =H3*G3*E3 -> 0 | V3: =I3*G3*E3 -> 0 | W3: =H3*G3*F3 -> 0 | X3: =I3*G3*F3 -> 0
A4: NJ Devils | B4: 3 | C4: 1 | D4: 0 | E4: 0 | F4: 0 | G4: 88 | H4: 0 | I4: 0 | J4: =H4+I4 -> 0 | K4: =(C4+D4)*(H4+I4) -> 0 | L4: =(E4+F4)*(H4+I4) -> 0 | M4: =C4*H4 -> 0 | N4: =D4*H4 -> 0 | O4: =E4*H4 -> 0 | P4: =F4*H4 -> 0 | Q4: =H4*G4*C4 -> 0 | R4: =I4*G4*C4 -> 0 | S4: =H4*G4*D4 -> 0 | T4: =I4*G4*D4 -> 0 | U4: =H4*G4*E4 -> 0 | V4: =I4*G4*E4 -> 0 | W4: =H4*G4*F4 -> 0 | X4: =I4*G4*F4 -> 0
A5: NY Islanders | B5: 4 | C5: 1 | D5: 0 | E5: 0 | F5: 0 | G5: 79 | H5: 0 | I5: 0 | J5: =H5+I5 -> 0 | K5: =(C5+D5)*(H5+I5) -> 0 | L5: =(E5+F5)*(H5+I5) -> 0 | M5: =C5*H5 -> 0 | N5: =D5*H5 -> 0 | O5: =E5*H5 -> 0 | P5: =F5*H5 -> 0 | Q5: =H5*G5*C5 -> 0 | R5: =I5*G5*C5 -> 0 | S5: =H5*G5*D5 -> 0 | T5: =I5*G5*D5 -> 0 | U5: =H5*G5*E5 -> 0 | V5: =I5*G5*E5 -> 0 | W5: =H5*G5*F5 -> 0 | X5: =I5*G5*F5 -> 0
A6: NY Rangers | B6: 5 | C6: 1 | D6: 0 | E6: 0 | F6: 0 | G6: 96 | H6: 0 | I6: 1 | J6: =H6+I6 -> 1 | K6: =(C6+D6)*(H6+I6) -> 1 | L6: =(E6+F6)*(H6+I6) -> 0 | M6: =C6*H6 -> 0 | N6: =D6*H6 -> 0 | O6: =E6*H6 -> 0 | P6: =F6*H6 -> 0 | Q6: =H6*G6*C6 -> 0 | R6: =I6*G6*C6 -> 96 | S6: =H6*G6*D6 -> 0 | T6: =I6*G6*D6 -> 0 | U6: =H6*G6*E6 -> 0 | V6: =I6*G6*E6 -> 0 | W6: =H6*G6*F6 -> 0 | X6: =I6*G6*F6 -> 0
A7: Philadelphia Flyers | B7: 6 | C7: 1 | D7: 0 | E7: 0 | F7: 0 | G7: 94 | H7: 0 | I7: 1 | J7: =H7+I7 -> 1 | K7: =(C7+D7)*(H7+I7) -> 1 | L7: =(E7+F7)*(H7+I7) -> 0 | M7: =C7*H7 -> 0 | N7: =D7*H7 -> 0 | O7: =E7*H7 -> 0 | P7: =F7*H7 -> 0 | Q7: =H7*G7*C7 -> 0 | R7: =I7*G7*C7 -> 94 | S7: =H7*G7*D7 -> 0 | T7: =I7*G7*D7 -> 0 | U7: =H7*G7*E7 -> 0 | V7: =I7*G7*E7 -> 0 | W7: =H7*G7*F7 -> 0 | X7: =I7*G7*F7 -> 0
A8: Pittsburg Penguins | B8: 7 | C8: 1 | D8: 0 | E8: 0 | F8: 0 | G8: 109 | H8: 0 | I8: 1 | J8: =H8+I8 -> 1 | K8: =(C8+D8)*(H8+I8) -> 1 | L8: =(E8+F8)*(H8+I8) -> 0 | M8: =C8*H8 -> 0 | N8: =D8*H8 -> 0 | O8: =E8*H8 -> 0 | P8: =F8*H8 -> 0 | Q8: =H8*G8*C8 -> 0 | R8: =I8*G8*C8 -> 109 | S8: =H8*G8*D8 -> 0 | T8: =I8*G8*D8 -> 0 | U8: =H8*G8*E8 -> 0 | V8: =I8*G8*E8 -> 0 | W8: =H8*G8*F8 -> 0 | X8: =I8*G8*F8 -> 0
A9: Washington Capitals | B9: 8 | C9: 1 | D9: 0 | E9: 0 | F9: 0 | G9: 90 | H9: 0 | I9: 0 | J9: =H9+I9 -> 0 | K9: =(C9+D9)*(H9+I9) -> 0 | L9: =(E9+F9)*(H9+I9) -> 0 | M9: =C9*H9 -> 0 | N9: =D9*H9 -> 0 | O9: =E9*H9 -> 0 | P9: =F9*H9 -> 0 | Q9: =H9*G9*C9 -> 0 | R9: =I9*G9*C9 -> 0 | S9: =H9*G9*D9 -> 0 | T9: =I9*G9*D9 -> 0 | U9: =H9*G9*E9 -> 0 | V9: =I9*G9*E9 -> 0 | W9: =H9*G9*F9 -> 0 | X9: =I9*G9*F9 -> 0
A10: Boston Bruins | B10: 9 | C10: 0 | D10: 1 | E10: 0 | F10: 0 | G10: 117 | H10: 0 | I10: 1 | J10: =H10+I10 -> 1 | K10: =(C10+D10)*(H10+I10) -> 1 | L10: =(E10+F10)*(H10+I10) -> 0 | M10: =C10*H10 -> 0 | N10: =D10*H10 -> 0 | O10: =E10*H10 -> 0 | P10: =F10*H10 -> 0 | Q10: =H10*G10*C10 -> 0 | R10: =I10*G10*C10 -> 0 | S10: =H10*G10*D10 -> 0 | T10: =I10*G10*D10 -> 117 | U10: =H10*G10*E10 -> 0 | V10: =I10*G10*E10 -> 0 | W10: =H10*G10*F10 -> 0 | X10: =I10*G10*F10 -> 0
A11: Buffalo Sabres | B11: 10 | C11: 0 | D11: 1 | E11: 0 | F11: 0 | G11: 52 | H11: 0 | I11: 0 | J11: =H11+I11 -> 0 | K11: =(C11+D11)*(H11+I11) -> 0 | L11: =(E11+F11)*(H11+I11) -> 0 | M11: =C11*H11 -> 0 | N11: =D11*H11 -> 0 | O11: =E11*H11 -> 0 | P11: =F11*H11 -> 0 | Q11: =H11*G11*C11 -> 0 | R11: =I11*G11*C11 -> 0 | S11: =H11*G11*D11 -> 0 | T11: =I11*G11*D11 -> 0 | U11: =H11*G11*E11 -> 0 | V11: =I11*G11*E11 -> 0 | W11: =H11*G11*F11 -> 0 | X11: =I11*G11*F11 -> 0
A12: Detroit Red Wings | B12: 11 | C12: 0 | D12: 1 | E12: 0 | F12: 0 | G12: 93 | H12: 0 | I12: 1 | J12: =H12+I12 -> 1 | K12: =(C12+D12)*(H12+I12) -> 1 | L12: =(E12+F12)*(H12+I12) -> 0 | M12: =C12*H12 -> 0 | N12: =D12*H12 -> 0 | O12: =E12*H12 -> 0 | P12: =F12*H12 -> 0 | Q12: =H12*G12*C12 -> 0 | R12: =I12*G12*C12 -> 0 | S12: =H12*G12*D12 -> 0 | T12: =I12*G12*D12 -> 93 | U12: =H12*G12*E12 -> 0 | V12: =I12*G12*E12 -> 0 | W12: =H12*G12*F12 -> 0 | X12: =I12*G12*F12 -> 0
A13: Florida Panthers | B13: 12 | C13: 0 | D13: 1 | E13: 0 | F13: 0 | G13: 66 | H13: 0 | I13: 0 | J13: =H13+I13 -> 0 | K13: =(C13+D13)*(H13+I13) -> 0 | L13: =(E13+F13)*(H13+I13) -> 0 | M13: =C13*H13 -> 0 | N13: =D13*H13 -> 0 | O13: =E13*H13 -> 0 | P13: =F13*H13 -> 0 | Q13: =H13*G13*C13 -> 0 | R13: =I13*G13*C13 -> 0 | S13: =H13*G13*D13 -> 0 | T13: =I13*G13*D13 -> 0 | U13: =H13*G13*E13 -> 0 | V13: =I13*G13*E13 -> 0 | W13: =H13*G13*F13 -> 0 | X13: =I13*G13*F13 -> 0
... A31: Vancouver Canucks | B31: 30 | C31: 0 | D31: 0 | E31: 0 | F31: 1 | G31: 83 | H31: 0 | I31: 0 | J31: =H31+I31 -> 0 | K31: =(C31+D31)*(H31+I31) -> 0 | L31: =(E31+F31)*(H31+I31) -> 0 | M31: =C31*H31 -> 0 | N31: =D31*H31 -> 0 | O31: =E31*H31 -> 0 | P31: =F31*H31 -> 0 | Q31: =H31*G31*C31 -> 0 | R31: =I31*G31*C31 -> 0 | S31: =H31*G31*D31 -> 0 | T31: =I31*G31*D31 -> 0 | U31: =H31*G31*E31 -> 0 | V31: =I31*G31*E31 -> 0 | W31: =H31*G31*F31 -> 0 | X31: =I31*G31*F31 -> 0
A33: Sum (if applicable) | H33: =SUM(H2:H31) -> 0 | I33: =SUM(I2:I31) -> 16 | K33: =SUM(K2:K31) -> 8 | L33: =SUM(L2:L31) -> 8 | O33: Don’t change | V33: Metropolitan Division (EC)
O34: don’t change, decision variables det values | V34: Atlantic Division (EC)
O35: decision variables | V35: Central Division (WC)
O36: change (based on points/point system) | V36: Pacific Division (WC)
Q40: Points
Q41: from top division: | R41: =SUMPRODUCT(G2:G31,H2:H31) -> 0
Q42: from wildcard: | R42: =SUMPRODUCT(G2:G31,I2:I31) -> 1649
T43: Actual total points to playoff:
Q44: Maximize | R44: =2*R41+R42 -> 1649 | T44: =R41+R42 -> 1649 | X44: *Also, updated that we want to prioritize being on top of their division over having a wildcard spot, so 2*points in top position + 1*points in wildcard
Q46: Subject to
R47: =SUM(H2:H31) +SUM(I2:I31) -> 16 | S47: .= | T47: 16
S48: <= | T48: 1
R49: =SUM(K2:K31) -> 8 | S49: <= | T49: 8
R50: =SUM(L2:L31) -> 8 | S50: <= | T50: 8
Q52: Eastern Conference | R52: =SUM(M2:M31) -> 0 | S52: .= | T52: =SUM(N2:N31) -> 0
Q53: Western Conference | R53: =SUM(O2:O31) -> 0 | S53: .= | T53: =SUM(P2:P31) -> 0
Q55: EC teams >= WC teams | R55: =R52 -> 0 | S55: >= | T55: =R53 -> 0
R56: This is to ensure EC have more teams than WC (this gets rid of the situation where WC > EC, making it unfair to EC teams in terms of points earned and guarantee of playoff spot)
Q58: Jen Added Constraints | R58: =SUMPRODUCT($H$2:$H$31,$C$2:$C$31) -> 0 | S58: <= | T58: 0 | U58: These constraints say that at most 4 teams from each division can make the playoff based on being top of their division.
R59: =SUMPRODUCT($H$2:$H$31,$D$2:$D$31) -> 0 | S59: <= | T59: 0
R60: =SUMPRODUCT($H$2:$H$31,$E$2:$E$31) -> 0 | S60: <= | T60: 0
R61: =SUMPRODUCT($H$2:$H$31,$F$2:$F$31) -> 0 | S61: <= | T61: 0

Sheet 14.1
A1: Team | B1: i | C1: mi | D1: ai | E1: ci | F1: pi | G1: ti - current system | H1: d1i | I1: d2i | J1: d1i+d2i | K1: (ai+mi)*(d1i+d2i) | L1: (ci+pi)* (d1i+d2i) | M1: mi*d1i | N1: ai*d1i | O1: ci*d1i | P1: pi*d1i | Q1: d1i*ti*mi | R1: d2i*ti*mi | S1: d1i*ti*ai | T1: d2i*ti*ai | U1: d1i*ti*ci | V1: d2i*ti*ci | W1: d1i*ti*pi | X1: d2i*ti*pi
A2: Carolina Hurricanes | B2: 1 | C2: 1 | D2: 0 | E2: 0 | F2: 0 | G2: 83 | H2: 0 | I2: 0 | J2: =H2+I2 -> 0 | K2: =(C2+D2)*(H2+I2) -> 0 | L2: =(E2+F2)*(H2+I2) -> 0 | M2: =C2*H2 -> 0 | N2: =D2*H2 -> 0 | O2: =E2*H2 -> 0 | P2: =F2*H2 -> 0 | Q2: =H2*G2*C2 -> 0 | R2: =I2*G2*C2 -> 0 | S2: =H2*G2*D2 -> 0 | T2: =I2*G2*D2 -> 0 | U2: =H2*G2*E2 -> 0 | V2: =I2*G2*E2 -> 0 | W2: =H2*G2*F2 -> 0 | X2: =I2*G2*F2 -> 0
A3: Columbus Blue Jackets | B3: 2 | C3: 1 | D3: 0 | E3: 0 | F3: 0 | G3: 93 | H3: 0 | I3: 1 | J3: =H3+I3 -> 1 | K3: =(C3+D3)*(H3+I3) -> 1 | L3: =(E3+F3)*(H3+I3) -> 0 | M3: =C3*H3 -> 0 | N3: =D3*H3 -> 0 | O3: =E3*H3 -> 0 | P3: =F3*H3 -> 0 | Q3: =H3*G3*C3 -> 0 | R3: =I3*G3*C3 -> 93 | S3: =H3*G3*D3 -> 0 | T3: =I3*G3*D3 -> 0 | U3: =H3*G3*E3 -> 0 | V3: =I3*G3*E3 -> 0 | W3: =H3*G3*F3 -> 0 | X3: =I3*G3*F3 -> 0
A4: NJ Devils | B4: 3 | C4: 1 | D4: 0 | E4: 0 | F4: 0 | G4: 88 | H4: 0 | I4: 0 | J4: =H4+I4 -> 0 | K4: =(C4+D4)*(H4+I4) -> 0 | L4: =(E4+F4)*(H4+I4) -> 0 | M4: =C4*H4 -> 0 | N4: =D4*H4 -> 0 | O4: =E4*H4 -> 0 | P4: =F4*H4 -> 0 | Q4: =H4*G4*C4 -> 0 | R4: =I4*G4*C4 -> 0 | S4: =H4*G4*D4 -> 0 | T4: =I4*G4*D4 -> 0 | U4: =H4*G4*E4 -> 0 | V4: =I4*G4*E4 -> 0 | W4: =H4*G4*F4 -> 0 | X4: =I4*G4*F4 -> 0
A5: NY Islanders | B5: 4 | C5: 1 | D5: 0 | E5: 0 | F5: 0 | G5: 79 | H5: 0 | I5: 0 | J5: =H5+I5 -> 0 | K5: =(C5+D5)*(H5+I5) -> 0 | L5: =(E5+F5)*(H5+I5) -> 0 | M5: =C5*H5 -> 0 | N5: =D5*H5 -> 0 | O5: =E5*H5 -> 0 | P5: =F5*H5 -> 0 | Q5: =H5*G5*C5 -> 0 | R5: =I5*G5*C5 -> 0 | S5: =H5*G5*D5 -> 0 | T5: =I5*G5*D5 -> 0 | U5: =H5*G5*E5 -> 0 | V5: =I5*G5*E5 -> 0 | W5: =H5*G5*F5 -> 0 | X5: =I5*G5*F5 -> 0
A6: NY Rangers | B6: 5 | C6: 1 | D6: 0 | E6: 0 | F6: 0 | G6: 96 | H6: 0 | I6: 1 | J6: =H6+I6 -> 1 | K6: =(C6+D6)*(H6+I6) -> 1 | L6: =(E6+F6)*(H6+I6) -> 0 | M6: =C6*H6 -> 0 | N6: =D6*H6 -> 0 | O6: =E6*H6 -> 0 | P6: =F6*H6 -> 0 | Q6: =H6*G6*C6 -> 0 | R6: =I6*G6*C6 -> 96 | S6: =H6*G6*D6 -> 0 | T6: =I6*G6*D6 -> 0 | U6: =H6*G6*E6 -> 0 | V6: =I6*G6*E6 -> 0 | W6: =H6*G6*F6 -> 0 | X6: =I6*G6*F6 -> 0
A7: Philadelphia Flyers | B7: 6 | C7: 1 | D7: 0 | E7: 0 | F7: 0 | G7: 94 | H7: 0 | I7: 1 | J7: =H7+I7 -> 1 | K7: =(C7+D7)*(H7+I7) -> 1 | L7: =(E7+F7)*(H7+I7) -> 0 | M7: =C7*H7 -> 0 | N7: =D7*H7 -> 0 | O7: =E7*H7 -> 0 | P7: =F7*H7 -> 0 | Q7: =H7*G7*C7 -> 0 | R7: =I7*G7*C7 -> 94 | S7: =H7*G7*D7 -> 0 | T7: =I7*G7*D7 -> 0 | U7: =H7*G7*E7 -> 0 | V7: =I7*G7*E7 -> 0 | W7: =H7*G7*F7 -> 0 | X7: =I7*G7*F7 -> 0
A8: Pittsburg Penguins | B8: 7 | C8: 1 | D8: 0 | E8: 0 | F8: 0 | G8: 109 | H8: 1 | I8: 0 | J8: =H8+I8 -> 1 | K8: =(C8+D8)*(H8+I8) -> 1 | L8: =(E8+F8)*(H8+I8) -> 0 | M8: =C8*H8 -> 1 | N8: =D8*H8 -> 0 | O8: =E8*H8 -> 0 | P8: =F8*H8 -> 0 | Q8: =H8*G8*C8 -> 109 | R8: =I8*G8*C8 -> 0 | S8: =H8*G8*D8 -> 0 | T8: =I8*G8*D8 -> 0 | U8: =H8*G8*E8 -> 0 | V8: =I8*G8*E8 -> 0 | W8: =H8*G8*F8 -> 0 | X8: =I8*G8*F8 -> 0
A9: Washington Capitals | B9: 8 | C9: 1 | D9: 0 | E9: 0 | F9: 0 | G9: 90 | H9: 0 | I9: 0 | J9: =H9+I9 -> 0 | K9: =(C9+D9)*(H9+I9) -> 0 | L9: =(E9+F9)*(H9+I9) -> 0 | M9: =C9*H9 -> 0 | N9: =D9*H9 -> 0 | O9: =E9*H9 -> 0 | P9: =F9*H9 -> 0 | Q9: =H9*G9*C9 -> 0 | R9: =I9*G9*C9 -> 0 | S9: =H9*G9*D9 -> 0 | T9: =I9*G9*D9 -> 0 | U9: =H9*G9*E9 -> 0 | V9: =I9*G9*E9 -> 0 | W9: =H9*G9*F9 -> 0 | X9: =I9*G9*F9 -> 0
A10: Boston Bruins | B10: 9 | C10: 0 | D10: 1 | E10: 0 | F10: 0 | G10: 117 | H10: 1 | I10: 0 | J10: =H10+I10 -> 1 | K10: =(C10+D10)*(H10+I10) -> 1 | L10: =(E10+F10)*(H10+I10) -> 0 | M10: =C10*H10 -> 0 | N10: =D10*H10 -> 1 | O10: =E10*H10 -> 0 | P10: =F10*H10 -> 0 | Q10: =H10*G10*C10 -> 0 | R10: =I10*G10*C10 -> 0 | S10: =H10*G10*D10 -> 117 | T10: =I10*G10*D10 -> 0 | U10: =H10*G10*E10 -> 0 | V10: =I10*G10*E10 -> 0 | W10: =H10*G10*F10 -> 0 | X10: =I10*G10*F10 -> 0
A11: Buffalo Sabres | B11: 10 | C11: 0 | D11: 1 | E11: 0 | F11: 0 | G11: 52 | H11: 0 | I11: 0 | J11: =H11+I11 -> 0 | K11: =(C11+D11)*(H11+I11) -> 0 | L11: =(E11+F11)*(H11+I11) -> 0 | M11: =C11*H11 -> 0 | N11: =D11*H11 -> 0 | O11: =E11*H11 -> 0 | P11: =F11*H11 -> 0 | Q11: =H11*G11*C11 -> 0 | R11: =I11*G11*C11 -> 0 | S11: =H11*G11*D11 -> 0 | T11: =I11*G11*D11 -> 0 | U11: =H11*G11*E11 -> 0 | V11: =I11*G11*E11 -> 0 | W11: =H11*G11*F11 -> 0 | X11: =I11*G11*F11 -> 0
A12: Detroit Red Wings | B12: 11 | C12: 0 | D12: 1 | E12: 0 | F12: 0 | G12: 93 | H12: 0 | I12: 1 | J12: =H12+I12 -> 1 | K12: =(C12+D12)*(H12+I12) -> 1 | L12: =(E12+F12)*(H12+I12) -> 0 | M12: =C12*H12 -> 0 | N12: =D12*H12 -> 0 | O12: =E12*H12 -> 0 | P12: =F12*H12 -> 0 | Q12: =H12*G12*C12 -> 0 | R12: =I12*G12*C12 -> 0 | S12: =H12*G12*D12 -> 0 | T12: =I12*G12*D12 -> 93 | U12: =H12*G12*E12 -> 0 | V12: =I12*G12*E12 -> 0 | W12: =H12*G12*F12 -> 0 | X12: =I12*G12*F12 -> 0
A13: Florida Panthers | B13: 12 | C13: 0 | D13: 1 | E13: 0 | F13: 0 | G13: 66 | H13: 0 | I13: 0 | J13: =H13+I13 -> 0 | K13: =(C13+D13)*(H13+I13) -> 0 | L13: =(E13+F13)*(H13+I13) -> 0 | M13: =C13*H13 -> 0 | N13: =D13*H13 -> 0 | O13: =E13*H13 -> 0 | P13: =F13*H13 -> 0 | Q13: =H13*G13*C13 -> 0 | R13: =I13*G13*C13 -> 0 | S13: =H13*G13*D13 -> 0 | T13: =I13*G13*D13 -> 0 | U13: =H13*G13*E13 -> 0 | V13: =I13*G13*E13 -> 0 | W13: =H13*G13*F13 -> 0 | X13: =I13*G13*F13 -> 0
... A31: Vancouver Canucks | B31: 30 | C31: 0 | D31: 0 | E31: 0 | F31: 1 | G31: 83 | H31: 0 | I31: 0 | J31: =H31+I31 -> 0 | K31: =(C31+D31)*(H31+I31) -> 0 | L31: =(E31+F31)*(H31+I31) -> 0 | M31: =C31*H31 -> 0 | N31: =D31*H31 -> 0 | O31: =E31*H31 -> 0 | P31: =F31*H31 -> 0 | Q31: =H31*G31*C31 -> 0 | R31: =I31*G31*C31 -> 0 | S31: =H31*G31*D31 -> 0 | T31: =I31*G31*D31 -> 0 | U31: =H31*G31*E31 -> 0 | V31: =I31*G31*E31 -> 0 | W31: =H31*G31*F31 -> 0 | X31: =I31*G31*F31 -> 0
A33: Sum (if applicable) | H33: =SUM(H2:H31) -> 4 | I33: =SUM(I2:I31) -> 12 | K33: =SUM(K2:K31) -> 8 | L33: =SUM(L2:L31) -> 8 | O33: Don’t change | V33: Metropolitan Division (EC)
O34: don’t change, decision variables det values | V34: Atlantic Division (EC)
O35: decision variables | V35: Central Division (WC)
O36: change (based on points/point system) | V36: Pacific Division (WC)
Q40: Points
Q41: from top division: | R41: =SUMPRODUCT(G2:G31,H2:H31) -> 454
Q42: from wildcard: | R42: =SUMPRODUCT(G2:G31,I2:I31) -> 1195
T43: Actual total points to playoff:
Q44: Maximize | R44: =2*R41+R42 -> 2103 | T44: =R41+R42 -> 1649 | X44: *Also, updated that we want to prioritize being on top of their division over having a wildcard spot, so 2*points in top position + 1*points in wildcard
Q46: Subject to
R47: =SUM(H2:H31) +SUM(I2:I31) -> 16 | S47: .= | T47: 16
S48: <= | T48: 1
R49: =SUM(K2:K31) -> 8 | S49: <= | T49: 8
R50: =SUM(L2:L31) -> 8 | S50: <= | T50: 8
Q52: Eastern Conference | R52: =SUM(M2:M31) -> 1 | S52: .= | T52: =SUM(N2:N31) -> 1
Q53: Western Conference | R53: =SUM(O2:O31) -> 1 | S53: .= | T53: =SUM(P2:P31) -> 1
Q55: EC teams >= WC teams | R55: =R52 -> 1 | S55: >= | T55: =R53 -> 1
R56: This is to ensure EC have more teams than WC (this gets rid of the situation where WC > EC, making it unfair to EC teams in terms of points earned and guarantee of playoff spot)
Q58: Jen Added Constraints | R58: =SUMPRODUCT($H$2:$H$31,$C$2:$C$31) -> 1 | S58: <= | T58: 1 | U58: These constraints say that at most 4 teams from each division can make the playoff based on being top of their division.
R59: =SUMPRODUCT($H$2:$H$31,$D$2:$D$31) -> 1 | S59: <= | T59: 1
R60: =SUMPRODUCT($H$2:$H$31,$E$2:$E$31) -> 1 | S60: <= | T60: 1
R61: =SUMPRODUCT($H$2:$H$31,$F$2:$F$31) -> 1 | S61: <= | T61: 1

Sheet 14.2
A1: Team | B1: i | C1: mi | D1: ai | E1: ci | F1: pi | G1: ti - current system | H1: d1i | I1: d2i | J1: d1i+d2i | K1: (ai+mi)*(d1i+d2i) | L1: (ci+pi)* (d1i+d2i) | M1: mi*d1i | N1: ai*d1i | O1: ci*d1i | P1: pi*d1i | Q1: d1i*ti*mi | R1: d2i*ti*mi | S1: d1i*ti*ai | T1: d2i*ti*ai | U1: d1i*ti*ci | V1: d2i*ti*ci | W1: d1i*ti*pi | X1: d2i*ti*pi
A2: Carolina Hurricanes | B2: 1 | C2: 1 | D2: 0 | E2: 0 | F2: 0 | G2: 83 | H2: 0 | I2: 0 | J2: =H2+I2 -> 0 | K2: =(C2+D2)*(H2+I2) -> 0 | L2: =(E2+F2)*(H2+I2) -> 0 | M2: =C2*H2 -> 0 | N2: =D2*H2 -> 0 | O2: =E2*H2 -> 0 | P2: =F2*H2 -> 0 | Q2: =H2*G2*C2 -> 0 | R2: =I2*G2*C2 -> 0 | S2: =H2*G2*D2 -> 0 | T2: =I2*G2*D2 -> 0 | U2: =H2*G2*E2 -> 0 | V2: =I2*G2*E2 -> 0 | W2: =H2*G2*F2 -> 0 | X2: =I2*G2*F2 -> 0
A3: Columbus Blue Jackets | B3: 2 | C3: 1 | D3: 0 | E3: 0 | F3: 0 | G3: 93 | H3: 0 | I3: 1 | J3: =H3+I3 -> 1 | K3: =(C3+D3)*(H3+I3) -> 1 | L3: =(E3+F3)*(H3+I3) -> 0 | M3: =C3*H3 -> 0 | N3: =D3*H3 -> 0 | O3: =E3*H3 -> 0 | P3: =F3*H3 -> 0 | Q3: =H3*G3*C3 -> 0 | R3: =I3*G3*C3 -> 93 | S3: =H3*G3*D3 -> 0 | T3: =I3*G3*D3 -> 0 | U3: =H3*G3*E3 -> 0 | V3: =I3*G3*E3 -> 0 | W3: =H3*G3*F3 -> 0 | X3: =I3*G3*F3 -> 0
A4: NJ Devils | B4: 3 | C4: 1 | D4: 0 | E4: 0 | F4: 0 | G4: 88 | H4: 0 | I4: 0 | J4: =H4+I4 -> 0 | K4: =(C4+D4)*(H4+I4) -> 0 | L4: =(E4+F4)*(H4+I4) -> 0 | M4: =C4*H4 -> 0 | N4: =D4*H4 -> 0 | O4: =E4*H4 -> 0 | P4: =F4*H4 -> 0 | Q4: =H4*G4*C4 -> 0 | R4: =I4*G4*C4 -> 0 | S4: =H4*G4*D4 -> 0 | T4: =I4*G4*D4 -> 0 | U4: =H4*G4*E4 -> 0 | V4: =I4*G4*E4 -> 0 | W4: =H4*G4*F4 -> 0 | X4: =I4*G4*F4 -> 0
A5: NY Islanders | B5: 4 | C5: 1 | D5: 0 | E5: 0 | F5: 0 | G5: 79 | H5: 0 | I5: 0 | J5: =H5+I5 -> 0 | K5: =(C5+D5)*(H5+I5) -> 0 | L5: =(E5+F5)*(H5+I5) -> 0 | M5: =C5*H5 -> 0 | N5: =D5*H5 -> 0 | O5: =E5*H5 -> 0 | P5: =F5*H5 -> 0 | Q5: =H5*G5*C5 -> 0 | R5: =I5*G5*C5 -> 0 | S5: =H5*G5*D5 -> 0 | T5: =I5*G5*D5 -> 0 | U5: =H5*G5*E5 -> 0 | V5: =I5*G5*E5 -> 0 | W5: =H5*G5*F5 -> 0 | X5: =I5*G5*F5 -> 0
A6: NY Rangers | B6: 5 | C6: 1 | D6: 0 | E6: 0 | F6: 0 | G6: 96 | H6: 1 | I6: 0 | J6: =H6+I6 -> 1 | K6: =(C6+D6)*(H6+I6) -> 1 | L6: =(E6+F6)*(H6+I6) -> 0 | M6: =C6*H6 -> 1 | N6: =D6*H6 -> 0 | O6: =E6*H6 -> 0 | P6: =F6*H6 -> 0 | Q6: =H6*G6*C6 -> 96 | R6: =I6*G6*C6 -> 0 | S6: =H6*G6*D6 -> 0 | T6: =I6*G6*D6 -> 0 | U6: =H6*G6*E6 -> 0 | V6: =I6*G6*E6 -> 0 | W6: =H6*G6*F6 -> 0 | X6: =I6*G6*F6 -> 0
A7: Philadelphia Flyers | B7: 6 | C7: 1 | D7: 0 | E7: 0 | F7: 0 | G7: 94 | H7: 0 | I7: 1 | J7: =H7+I7 -> 1 | K7: =(C7+D7)*(H7+I7) -> 1 | L7: =(E7+F7)*(H7+I7) -> 0 | M7: =C7*H7 -> 0 | N7: =D7*H7 -> 0 | O7: =E7*H7 -> 0 | P7: =F7*H7 -> 0 | Q7: =H7*G7*C7 -> 0 | R7: =I7*G7*C7 -> 94 | S7: =H7*G7*D7 -> 0 | T7: =I7*G7*D7 -> 0 | U7: =H7*G7*E7 -> 0 | V7: =I7*G7*E7 -> 0 | W7: =H7*G7*F7 -> 0 | X7: =I7*G7*F7 -> 0
A8: Pittsburg Penguins | B8: 7 | C8: 1 | D8: 0 | E8: 0 | F8: 0 | G8: 109 | H8: 1 | I8: 0 | J8: =H8+I8 -> 1 | K8: =(C8+D8)*(H8+I8) -> 1 | L8: =(E8+F8)*(H8+I8) -> 0 | M8: =C8*H8 -> 1 | N8: =D8*H8 -> 0 | O8: =E8*H8 -> 0 | P8: =F8*H8 -> 0 | Q8: =H8*G8*C8 -> 109 | R8: =I8*G8*C8 -> 0 | S8: =H8*G8*D8 -> 0 | T8: =I8*G8*D8 -> 0 | U8: =H8*G8*E8 -> 0 | V8: =I8*G8*E8 -> 0 | W8: =H8*G8*F8 -> 0 | X8: =I8*G8*F8 -> 0
A9: Washington Capitals | B9: 8 | C9: 1 | D9: 0 | E9: 0 | F9: 0 | G9: 90 | H9: 0 | I9: 0 | J9: =H9+I9 -> 0 | K9: =(C9+D9)*(H9+I9) -> 0 | L9: =(E9+F9)*(H9+I9) -> 0 | M9: =C9*H9 -> 0 | N9: =D9*H9 -> 0 | O9: =E9*H9 -> 0 | P9: =F9*H9 -> 0 | Q9: =H9*G9*C9 -> 0 | R9: =I9*G9*C9 -> 0 | S9: =H9*G9*D9 -> 0 | T9: =I9*G9*D9 -> 0 | U9: =H9*G9*E9 -> 0 | V9: =I9*G9*E9 -> 0 | W9: =H9*G9*F9 -> 0 | X9: =I9*G9*F9 -> 0
A10: Boston Bruins | B10: 9 | C10: 0 | D10: 1 | E10: 0 | F10: 0 | G10: 117 | H10: 1 | I10: 0 | J10: =H10+I10 -> 1 | K10: =(C10+D10)*(H10+I10) -> 1 | L10: =(E10+F10)*(H10+I10) -> 0 | M10: =C10*H10 -> 0 | N10: =D10*H10 -> 1 | O10: =E10*H10 -> 0 | P10: =F10*H10 -> 0 | Q10: =H10*G10*C10 -> 0 | R10: =I10*G10*C10 -> 0 | S10: =H10*G10*D10 -> 117 | T10: =I10*G10*D10 -> 0 | U10: =H10*G10*E10 -> 0 | V10: =I10*G10*E10 -> 0 | W10: =H10*G10*F10 -> 0 | X10: =I10*G10*F10 -> 0
A11: Buffalo Sabres | B11: 10 | C11: 0 | D11: 1 | E11: 0 | F11: 0 | G11: 52 | H11: 0 | I11: 0 | J11: =H11+I11 -> 0 | K11: =(C11+D11)*(H11+I11) -> 0 | L11: =(E11+F11)*(H11+I11) -> 0 | M11: =C11*H11 -> 0 | N11: =D11*H11 -> 0 | O11: =E11*H11 -> 0 | P11: =F11*H11 -> 0 | Q11: =H11*G11*C11 -> 0 | R11: =I11*G11*C11 -> 0 | S11: =H11*G11*D11 -> 0 | T11: =I11*G11*D11 -> 0 | U11: =H11*G11*E11 -> 0 | V11: =I11*G11*E11 -> 0 | W11: =H11*G11*F11 -> 0 | X11: =I11*G11*F11 -> 0
A12: Detroit Red Wings | B12: 11 | C12: 0 | D12: 1 | E12: 0 | F12: 0 | G12: 93 | H12: 0 | I12: 1 | J12: =H12+I12 -> 1 | K12: =(C12+D12)*(H12+I12) -> 1 | L12: =(E12+F12)*(H12+I12) -> 0 | M12: =C12*H12 -> 0 | N12: =D12*H12 -> 0 | O12: =E12*H12 -> 0 | P12: =F12*H12 -> 0 | Q12: =H12*G12*C12 -> 0 | R12: =I12*G12*C12 -> 0 | S12: =H12*G12*D12 -> 0 | T12: =I12*G12*D12 -> 93 | U12: =H12*G12*E12 -> 0 | V12: =I12*G12*E12 -> 0 | W12: =H12*G12*F12 -> 0 | X12: =I12*G12*F12 -> 0
A13: Florida Panthers | B13: 12 | C13: 0 | D13: 1 | E13: 0 | F13: 0 | G13: 66 | H13: 0 | I13: 0 | J13: =H13+I13 -> 0 | K13: =(C13+D13)*(H13+I13) -> 0 | L13: =(E13+F13)*(H13+I13) -> 0 | M13: =C13*H13 -> 0 | N13: =D13*H13 -> 0 | O13: =E13*H13 -> 0 | P13: =F13*H13 -> 0 | Q13: =H13*G13*C13 -> 0 | R13: =I13*G13*C13 -> 0 | S13: =H13*G13*D13 -> 0 | T13: =I13*G13*D13 -> 0 | U13: =H13*G13*E13 -> 0 | V13: =I13*G13*E13 -> 0 | W13: =H13*G13*F13 -> 0 | X13: =I13*G13*F13 -> 0
... A31: Vancouver Canucks | B31: 30 | C31: 0 | D31: 0 | E31: 0 | F31: 1 | G31: 83 | H31: 0 | I31: 0 | J31: =H31+I31 -> 0 | K31: =(C31+D31)*(H31+I31) -> 0 | L31: =(E31+F31)*(H31+I31) -> 0 | M31: =C31*H31 -> 0 | N31: =D31*H31 -> 0 | O31: =E31*H31 -> 0 | P31: =F31*H31 -> 0 | Q31: =H31*G31*C31 -> 0 | R31: =I31*G31*C31 -> 0 | S31: =H31*G31*D31 -> 0 | T31: =I31*G31*D31 -> 0 | U31: =H31*G31*E31 -> 0 | V31: =I31*G31*E31 -> 0 | W31: =H31*G31*F31 -> 0 | X31: =I31*G31*F31 -> 0
A33: Sum (if applicable) | H33: =SUM(H2:H31) -> 8 | I33: =SUM(I2:I31) -> 8 | K33: =SUM(K2:K31) -> 8 | L33: =SUM(L2:L31) -> 8 | O33: Don’t change | V33: Metropolitan Division (EC)
O34: don’t change, decision variables det values | V34: Atlantic Division (EC)
O35: decision variables | V35: Central Division (WC)
O36: change (based on points/point system) | V36: Pacific Division (WC)
Q40: Points
Q41: from top division: | R41: =SUMPRODUCT(G2:G31,H2:H31) -> 873
Q42: from wildcard: | R42: =SUMPRODUCT(G2:G31,I2:I31) -> 776
T43: Actual total points to playoff:
Q44: Maximize | R44: =2*R41+R42 -> 2522 | T44: =R41+R42 -> 1649 | X44: *Also, updated that we want to prioritize being on top of their division over having a wildcard spot, so 2*points in top position + 1*points in wildcard
Q46: Subject to
R47: =SUM(H2:H31) +SUM(I2:I31) -> 16 | S47: .= | T47: 16
S48: <= | T48: 1
R49: =SUM(K2:K31) -> 8 | S49: <= | T49: 8
R50: =SUM(L2:L31) -> 8 | S50: <= | T50: 8
Q52: Eastern Conference | R52: =SUM(M2:M31) -> 2 | S52: .= | T52: =SUM(N2:N31) -> 2
Q53: Western Conference | R53: =SUM(O2:O31) -> 2 | S53: .= | T53: =SUM(P2:P31) -> 2
Q55: EC teams >= WC teams | R55: =R52 -> 2 | S55: >= | T55: =R53 -> 2
R56: This is to ensure EC have more teams than WC (this gets rid of the situation where WC > EC, making it unfair to EC teams in terms of points earned and guarantee of playoff spot)
Q58: Jen Added Constraints | R58: =SUMPRODUCT($H$2:$H$31,$C$2:$C$31) -> 2 | S58: <= | T58: 2 | U58: These constraints say that at most 4 teams from each division can make the playoff based on being top of their division.
R59: =SUMPRODUCT($H$2:$H$31,$D$2:$D$31) -> 2 | S59: <= | T59: 2
R60: =SUMPRODUCT($H$2:$H$31,$E$2:$E$31) -> 2 | S60: <= | T60: 2
R61: =SUMPRODUCT($H$2:$H$31,$F$2:$F$31) -> 2 | S61: <= | T61: 2

Sheet 14.3 - model of cur system
A1: Team | B1: i | C1: mi | D1: ai | E1: ci | F1: pi | G1: ti - current system | H1: d1i | I1: d2i | J1: d1i+d2i | K1: (ai+mi)*(d1i+d2i) | L1: (ci+pi)* (d1i+d2i) | M1: mi*d1i | N1: ai*d1i | O1: ci*d1i | P1: pi*d1i | Q1: d1i*ti*mi | R1: d2i*ti*mi | S1: d1i*ti*ai | T1: d2i*ti*ai | U1: d1i*ti*ci | V1: d2i*ti*ci | W1: d1i*ti*pi | X1: d2i*ti*pi
A2: Carolina Hurricanes | B2: 1 | C2: 1 | D2: 0 | E2: 0 | F2: 0 | G2: 113 | H2: 0 | I2: 0 | J2: =H2+I2 -> 0 | K2: =(C2+D2)*(H2+I2) -> 0 | L2: =(E2+F2)*(H2+I2) -> 0 | M2: =C2*H2 -> 0 | N2: =D2*H2 -> 0 | O2: =E2*H2 -> 0 | P2: =F2*H2 -> 0 | Q2: =H2*G2*C2 -> 0 | R2: =I2*G2*C2 -> 0 | S2: =H2*G2*D2 -> 0 | T2: =I2*G2*D2 -> 0 | U2: =H2*G2*E2 -> 0 | V2: =I2*G2*E2 -> 0 | W2: =H2*G2*F2 -> 0 | X2: =I2*G2*F2 -> 0
A3: Columbus Blue Jackets | B3: 2 | C3: 1 | D3: 0 | E3: 0 | F3: 0 | G3: 128 | H3: 0 | I3: 1 | J3: =H3+I3 -> 1 | K3: =(C3+D3)*(H3+I3) -> 1 | L3: =(E3+F3)*(H3+I3) -> 0 | M3: =C3*H3 -> 0 | N3: =D3*H3 -> 0 | O3: =E3*H3 -> 0 | P3: =F3*H3 -> 0 | Q3: =H3*G3*C3 -> 0 | R3: =I3*G3*C3 -> 128 | S3: =H3*G3*D3 -> 0 | T3: =I3*G3*D3 -> 0 | U3: =H3*G3*E3 -> 0 | V3: =I3*G3*E3 -> 0 | W3: =H3*G3*F3 -> 0 | X3: =I3*G3*F3 -> 0
A4: NJ Devils | B4: 3 | C4: 1 | D4: 0 | E4: 0 | F4: 0 | G4: 114 | H4: 0 | I4: 0 | J4: =H4+I4 -> 0 | K4: =(C4+D4)*(H4+I4) -> 0 | L4: =(E4+F4)*(H4+I4) -> 0 | M4: =C4*H4 -> 0 | N4: =D4*H4 -> 0 | O4: =E4*H4 -> 0 | P4: =F4*H4 -> 0 | Q4: =H4*G4*C4 -> 0 | R4: =I4*G4*C4 -> 0 | S4: =H4*G4*D4 -> 0 | T4: =I4*G4*D4 -> 0 | U4: =H4*G4*E4 -> 0 | V4: =I4*G4*E4 -> 0 | W4: =H4*G4*F4 -> 0 | X4: =I4*G4*F4 -> 0
A5: NY Islanders | B5: 4 | C5: 1 | D5: 0 | E5: 0 | F5: 0 | H5: 0 | I5: 0 | J5: =H5+I5 -> 0 | K5: =(C5+D5)*(H5+I5) -> 0 | L5: =(E5+F5)*(H5+I5) -> 0 | M5: =C5*H5 -> 0 | N5: =D5*H5 -> 0 | O5: =E5*H5 -> 0 | P5: =F5*H5 -> 0 | Q5: =H5*G5*C5 -> 0 | R5: =I5*G5*C5 -> 0 | S5: =H5*G5*D5 -> 0 | T5: =I5*G5*D5 -> 0 | U5: =H5*G5*E5 -> 0 | V5: =I5*G5*E5 -> 0 | W5: =H5*G5*F5 -> 0 | X5: =I5*G5*F5 -> 0
A6: NY Rangers | B6: 5 | C6: 1 | D6: 0 | E6: 0 | F6: 0 | G6: 135 | H6: 1 | I6: 0 | J6: =H6+I6 -> 1 | K6: =(C6+D6)*(H6+I6) -> 1 | L6: =(E6+F6)*(H6+I6) -> 0 | M6: =C6*H6 -> 1 | N6: =D6*H6 -> 0 | O6: =E6*H6 -> 0 | P6: =F6*H6 -> 0 | Q6: =H6*G6*C6 -> 135 | R6: =I6*G6*C6 -> 0 | S6: =H6*G6*D6 -> 0 | T6: =I6*G6*D6 -> 0 | U6: =H6*G6*E6 -> 0 | V6: =I6*G6*E6 -> 0 | W6: =H6*G6*F6 -> 0 | X6: =I6*G6*F6 -> 0
A7: Philadelphia Flyers | B7: 6 | C7: 1 | D7: 0 | E7: 0 | F7: 0 | G7: 129 | H7: 1 | I7: 0 | J7: =H7+I7 -> 1 | K7: =(C7+D7)*(H7+I7) -> 1 | L7: =(E7+F7)*(H7+I7) -> 0 | M7: =C7*H7 -> 1 | N7: =D7*H7 -> 0 | O7: =E7*H7 -> 0 | P7: =F7*H7 -> 0 | Q7: =H7*G7*C7 -> 129 | R7: =I7*G7*C7 -> 0 | S7: =H7*G7*D7 -> 0 | T7: =I7*G7*D7 -> 0 | U7: =H7*G7*E7 -> 0 | V7: =I7*G7*E7 -> 0 | W7: =H7*G7*F7 -> 0 | X7: =I7*G7*F7 -> 0
A8: Pittsburg Penguins | B8: 7 | C8: 1 | D8: 0 | E8: 0 | F8: 0 | G8: 149 | H8: 1 | I8: 0 | J8: =H8+I8 -> 1 | K8: =(C8+D8)*(H8+I8) -> 1 | L8: =(E8+F8)*(H8+I8) -> 0 | M8: =C8*H8 -> 1 | N8: =D8*H8 -> 0 | O8: =E8*H8 -> 0 | P8: =F8*H8 -> 0 | Q8: =H8*G8*C8 -> 149 | R8: =I8*G8*C8 -> 0 | S8: =H8*G8*D8 -> 0 | T8: =I8*G8*D8 -> 0 | U8: =H8*G8*E8 -> 0 | V8: =I8*G8*E8 -> 0 | W8: =H8*G8*F8 -> 0 | X8: =I8*G8*F8 -> 0
A9: Washington Capitals | B9: 8 | C9: 1 | D9: 0 | E9: 0 | F9: 0 | G9: 114 | H9: 0 | I9: 0 | J9: =H9+I9 -> 0 | K9: =(C9+D9)*(H9+I9) -> 0 | L9: =(E9+F9)*(H9+I9) -> 0 | M9: =C9*H9 -> 0 | N9: =D9*H9 -> 0 | O9: =E9*H9 -> 0 | P9: =F9*H9 -> 0 | Q9: =H9*G9*C9 -> 0 | R9: =I9*G9*C9 -> 0 | S9: =H9*G9*D9 -> 0 | T9: =I9*G9*D9 -> 0 | U9: =H9*G9*E9 -> 0 | V9: =I9*G9*E9 -> 0 | W9: =H9*G9*F9 -> 0 | X9: =I9*G9*F9 -> 0
A10: Boston Bruins | B10: 9 | C10: 0 | D10: 1 | E10: 0 | F10: 0 | G10: 164 | H10: 1 | I10: 0 | J10: =H10+I10 -> 1 | K10: =(C10+D10)*(H10+I10) -> 1 | L10: =(E10+F10)*(H10+I10) -> 0 | M10: =C10*H10 -> 0 | N10: =D10*H10 -> 1 | O10: =E10*H10 -> 0 | P10: =F10*H10 -> 0 | Q10: =H10*G10*C10 -> 0 | R10: =I10*G10*C10 -> 0 | S10: =H10*G10*D10 -> 164 | T10: =I10*G10*D10 -> 0 | U10: =H10*G10*E10 -> 0 | V10: =I10*G10*E10 -> 0 | W10: =H10*G10*F10 -> 0 | X10: =I10*G10*F10 -> 0
A11: Buffalo Sabres | B11: 10 | C11: 0 | D11: 1 | E11: 0 | F11: 0 | H11: 0 | I11: 0 | J11: =H11+I11 -> 0 | K11: =(C11+D11)*(H11+I11) -> 0 | L11: =(E11+F11)*(H11+I11) -> 0 | M11: =C11*H11 -> 0 | N11: =D11*H11 -> 0 | O11: =E11*H11 -> 0 | P11: =F11*H11 -> 0 | Q11: =H11*G11*C11 -> 0 | R11: =I11*G11*C11 -> 0 | S11: =H11*G11*D11 -> 0 | T11: =I11*G11*D11 -> 0 | U11: =H11*G11*E11 -> 0 | V11: =I11*G11*E11 -> 0 | W11: =H11*G11*F11 -> 0 | X11: =I11*G11*F11 -> 0
A12: Detroit Red Wings | B12: 11 | C12: 0 | D12: 1 | E12: 0 | F12: 0 | G12: 123 | H12: 0 | I12: 1 | J12: =H12+I12 -> 1 | K12: =(C12+D12)*(H12+I12) -> 1 | L12: =(E12+F12)*(H12+I12) -> 0 | M12: =C12*H12 -> 0 | N12: =D12*H12 -> 0 | O12: =E12*H12 -> 0 | P12: =F12*H12 -> 0 | Q12: =H12*G12*C12 -> 0 | R12: =I12*G12*C12 -> 0 | S12: =H12*G12*D12 -> 0 | T12: =I12*G12*D12 -> 123 | U12: =H12*G12*E12 -> 0 | V12: =I12*G12*E12 -> 0 | W12: =H12*G12*F12 -> 0 | X12: =I12*G12*F12 -> 0
A13: Florida Panthers | B13: 12 | C13: 0 | D13: 1 | E13: 0 | F13: 0 | H13: 0 | I13: 0 | J13: =H13+I13 -> 0 | K13: =(C13+D13)*(H13+I13) -> 0 | L13: =(E13+F13)*(H13+I13) -> 0 | M13: =C13*H13 -> 0 | N13: =D13*H13 -> 0 | O13: =E13*H13 -> 0 | P13: =F13*H13 -> 0 | Q13: =H13*G13*C13 -> 0 | R13: =I13*G13*C13 -> 0 | S13: =H13*G13*D13 -> 0 | T13: =I13*G13*D13 -> 0 | U13: =H13*G13*E13 -> 0 | V13: =I13*G13*E13 -> 0 | W13: =H13*G13*F13 -> 0 | X13: =I13*G13*F13 -> 0
A14: Montreal Canadiens | B14: 13 | C14: 0 | D14: 1 | E14: 0 | F14: 0 | G14: 133 | H14: 1 | I14: 0 | J14: =H14+I14 -> 1 | K14: =(C14+D14)*(H14+I14) -> 1 | L14: =(E14+F14)*(H14+I14) -> 0 | M14: =C14*H14 -> 0 | N14: =D14*H14 -> 1 | O14: =E14*H14 -> 0 | P14: =F14*H14 -> 0 | Q14: =H14*G14*C14 -> 0 | R14: =I14*G14*C14 -> 0 | S14: =H14*G14*D14 -> 133 | T14: =I14*G14*D14 -> 0 | U14: =H14*G14*E14 -> 0 | V14: =I14*G14*E14 -> 0 | W14: =H14*G14*F14 -> 0 | X14: =I14*G14*F14 -> 0
A15: Ottawa Senators | B15: 14 | C15: 0 | D15: 1 | E15: 0 | F15: 0 | G15: 115 | H15: 0 | I15: 0 | J15: =H15+I15 -> 0 | K15: =(C15+D15)*(H15+I15) -> 0 | L15: =(E15+F15)*(H15+I15) -> 0 | M15: =C15*H15 -> 0 | N15: =D15*H15 -> 0 | O15: =E15*H15 -> 0 | P15: =F15*H15 -> 0 | Q15: =H15*G15*C15 -> 0 | R15: =I15*G15*C15 -> 0 | S15: =H15*G15*D15 -> 0 | T15: =I15*G15*D15 -> 0 | U15: =H15*G15*E15 -> 0 | V15: =I15*G15*E15 -> 0 | W15: =H15*G15*F15 -> 0 | X15: =I15*G15*F15 -> 0
A16: Tampa Bay Lightning | B16: 15 | C16: 0 | D16: 1 | E16: 0 | F16: 0 | G16: 133 | H16: 1 | I16: 0 | J16: =H16+I16 -> 1 | K16: =(C16+D16)*(H16+I16) -> 1 | L16: =(E16+F16)*(H16+I16) -> 0 | M16: =C16*H16 -> 0 | N16: =D16*H16 -> 1 | O16: =E16*H16 -> 0 | P16: =F16*H16 -> 0 | Q16: =H16*G16*C16 -> 0 | R16: =I16*G16*C16 -> 0 | S16: =H16*G16*D16 -> 133 | T16: =I16*G16*D16 -> 0 | U16: =H16*G16*E16 -> 0 | V16: =I16*G16*E16 -> 0 | W16: =H16*G16*F16 -> 0 | X16: =I16*G16*F16 -> 0
A17: Toronto Maple Leafs | B17: 16 | C17: 0 | D17: 1 | E17: 0 | F17: 0 | G17: 108 | H17: 0 | I17: 0 | J17: =H17+I17 -> 0 | K17: =(C17+D17)*(H17+I17) -> 0 | L17: =(E17+F17)*(H17+I17) -> 0 | M17: =C17*H17 -> 0 | N17: =D17*H17 -> 0 | O17: =E17*H17 -> 0 | P17: =F17*H17 -> 0 | Q17: =H17*G17*C17 -> 0 | R17: =I17*G17*C17 -> 0 | S17: =H17*G17*D17 -> 0 | T17: =I17*G17*D17 -> 0 | U17: =H17*G17*E17 -> 0 | V17: =I17*G17*E17 -> 0 | W17: =H17*G17*F17 -> 0 | X17: =I17*G17*F17 -> 0
A18: Chicago Blackhawks | B18: 17 | C18: 0 | D18: 0 | E18: 1 | F18: 0 | G18: 146 | H18: 1 | I18: 0 | J18: =H18+I18 -> 1 | K18: =(C18+D18)*(H18+I18) -> 0 | L18: =(E18+F18)*(H18+I18) -> 1 | M18: =C18*H18 -> 0 | N18: =D18*H18 -> 0 | O18: =E18*H18 -> 1 | P18: =F18*H18 -> 0 | Q18: =H18*G18*C18 -> 0 | R18: =I18*G18*C18 -> 0 | S18: =H18*G18*D18 -> 0 | T18: =I18*G18*D18 -> 0 | U18: =H18*G18*E18 -> 146 | V18: =I18*G18*E18 -> 0 | W18: =H18*G18*F18 -> 0 | X18: =I18*G18*F18 -> 0
A19: Colorado Avalanche | B19: 18 | C19: 0 | D19: 0 | E19: 1 | F19: 0 | G19: 149 | H19: 1 | I19: 0 | J19: =H19+I19 -> 1 | K19: =(C19+D19)*(H19+I19) -> 0 | L19: =(E19+F19)*(H19+I19) -> 1 | M19: =C19*H19 -> 0 | N19: =D19*H19 -> 0 | O19: =E19*H19 -> 1 | P19: =F19*H19 -> 0 | Q19: =H19*G19*C19 -> 0 | R19: =I19*G19*C19 -> 0 | S19: =H19*G19*D19 -> 0 | T19: =I19*G19*D19 -> 0 | U19: =H19*G19*E19 -> 149 | V19: =I19*G19*E19 -> 0 | W19: =H19*G19*F19 -> 0 | X19: =I19*G19*F19 -> 0
A20: Dallas Stars | B20: 19 | C20: 0 | D20: 0 | E20: 1 | F20: 0 | G20: 125 | H20: 0 | I20: 1 | J20: =H20+I20 -> 1 | K20: =(C20+D20)*(H20+I20) -> 0 | L20: =(E20+F20)*(H20+I20) -> 1 | M20: =C20*H20 -> 0 | N20: =D20*H20 -> 0 | O20: =E20*H20 -> 0 | P20: =F20*H20 -> 0 | Q20: =H20*G20*C20 -> 0 | R20: =I20*G20*C20 -> 0 | S20: =H20*G20*D20 -> 0 | T20: =I20*G20*D20 -> 0 | U20: =H20*G20*E20 -> 0 | V20: =I20*G20*E20 -> 125 | W20: =H20*G20*F20 -> 0 | X20: =I20*G20*F20 -> 0
A21: Minnesota Wild | B21: 20 | C21: 0 | D21: 0 | E21: 1 | F21: 0 | G21: 130 | H21: 0 | I21: 1 | J21: =H21+I21 -> 1 | K21: =(C21+D21)*(H21+I21) -> 0 | L21: =(E21+F21)*(H21+I21) -> 1 | M21: =C21*H21 -> 0 | N21: =D21*H21 -> 0 | O21: =E21*H21 -> 0 | P21: =F21*H21 -> 0 | Q21: =H21*G21*C21 -> 0 | R21: =I21*G21*C21 -> 0 | S21: =H21*G21*D21 -> 0 | T21: =I21*G21*D21 -> 0 | U21: =H21*G21*E21 -> 0 | V21: =I21*G21*E21 -> 130 | W21: =H21*G21*F21 -> 0 | X21: =I21*G21*F21 -> 0
A22: Nashville Predators | B22: 21 | C22: 0 | D22: 0 | E22: 1 | F22: 0 | G22: 121 | H22: 0 | I22: 0 | J22: =H22+I22 -> 0 | K22: =(C22+D22)*(H22+I22) -> 0 | L22: =(E22+F22)*(H22+I22) -> 0 | M22: =C22*H22 -> 0 | N22: =D22*H22 -> 0 | O22: =E22*H22 -> 0 | P22: =F22*H22 -> 0 | Q22: =H22*G22*C22 -> 0 | R22: =I22*G22*C22 -> 0 | S22: =H22*G22*D22 -> 0 | T22: =I22*G22*D22 -> 0 | U22: =H22*G22*E22 -> 0 | V22: =I22*G22*E22 -> 0 | W22: =H22*G22*F22 -> 0 | X22: =I22*G22*F22 -> 0
A23: St. Louis Blues | B23: 22 | C23: 0 | D23: 0 | E23: 1 | F23: 0 | G23: 151 | H23: 1 | I23: 0 | J23: =H23+I23 -> 1 | K23: =(C23+D23)*(H23+I23) -> 0 | L23: =(E23+F23)*(H23+I23) -> 1 | M23: =C23*H23 -> 0 | N23: =D23*H23 -> 0 | O23: =E23*H23 -> 1 | P23: =F23*H23 -> 0 | Q23: =H23*G23*C23 -> 0 | R23: =I23*G23*C23 -> 0 | S23: =H23*G23*D23 -> 0 | T23: =I23*G23*D23 -> 0 | U23: =H23*G23*E23 -> 151 | V23: =I23*G23*E23 -> 0 | W23: =H23*G23*F23 -> 0 | X23: =I23*G23*F23 -> 0
A24: Winnipeg Jets | B24: 23 | C24: 0 | D24: 0 | E24: 1 | F24: 0 | G24: 108 | H24: 0 | I24: 0 | J24: =H24+I24 -> 0 | K24: =(C24+D24)*(H24+I24) -> 0 | L24: =(E24+F24)*(H24+I24) -> 0 | M24: =C24*H24 -> 0 | N24: =D24*H24 -> 0 | O24: =E24*H24 -> 0 | P24: =F24*H24 -> 0 | Q24: =H24*G24*C24 -> 0 | R24: =I24*G24*C24 -> 0 | S24: =H24*G24*D24 -> 0 | T24: =I24*G24*D24 -> 0 | U24: =H24*G24*E24 -> 0 | V24: =I24*G24*E24 -> 0 | W24: =H24*G24*F24 -> 0 | X24: =I24*G24*F24 -> 0
A25: Anaheim Ducks | B25: 24 | C25: 0 | D25: 0 | E25: 0 | F25: 1 | G25: 160 | H25: 1 | I25: 0 | J25: =H25+I25 -> 1 | K25: =(C25+D25)*(H25+I25) -> 0 | L25: =(E25+F25)*(H25+I25) -> 1 | M25: =C25*H25 -> 0 | N25: =D25*H25 -> 0 | O25: =E25*H25 -> 0 | P25: =F25*H25 -> 1 | Q25: =H25*G25*C25 -> 0 | R25: =I25*G25*C25 -> 0 | S25: =H25*G25*D25 -> 0 | T25: =I25*G25*D25 -> 0 | U25: =H25*G25*E25 -> 0 | V25: =I25*G25*E25 -> 0 | W25: =H25*G25*F25 -> 160 | X25: =I25*G25*F25 -> 0
A26: Arizona Coyotes | B26: 25 | C26: 0 | D26: 0 | E26: 0 | F26: 1 | G26: 117 | H26: 0 | I26: 0 | J26: =H26+I26 -> 0 | K26: =(C26+D26)*(H26+I26) -> 0 | L26: =(E26+F26)*(H26+I26) -> 0 | M26: =C26*H26 -> 0 | N26: =D26*H26 -> 0 | O26: =E26*H26 -> 0 | P26: =F26*H26 -> 0 | Q26: =H26*G26*C26 -> 0 | R26: =I26*G26*C26 -> 0 | S26: =H26*G26*D26 -> 0 | T26: =I26*G26*D26 -> 0 | U26: =H26*G26*E26 -> 0 | V26: =I26*G26*E26 -> 0 | W26: =H26*G26*F26 -> 0 | X26: =I26*G26*F26 -> 0
A27: Calgary Flames | B27: 26 | C27: 0 | D27: 0 | E27: 0 | F27: 1 | H27: 0 | I27: 0 | J27: =H27+I27 -> 0 | K27: =(C27+D27)*(H27+I27) -> 0 | L27: =(E27+F27)*(H27+I27) -> 0 | M27: =C27*H27 -> 0 | N27: =D27*H27 -> 0 | O27: =E27*H27 -> 0 | P27: =F27*H27 -> 0 | Q27: =H27*G27*C27 -> 0 | R27: =I27*G27*C27 -> 0 | S27: =H27*G27*D27 -> 0 | T27: =I27*G27*D27 -> 0 | U27: =H27*G27*E27 -> 0 | V27: =I27*G27*E27 -> 0 | W27: =H27*G27*F27 -> 0 | X27: =I27*G27*F27 -> 0
A28: Edmonton Oilers | B28: 27 | C28: 0 | D28: 0 | E28: 0 | F28: 1 | H28: 0 | I28: 0 | J28: =H28+I28 -> 0 | K28: =(C28+D28)*(H28+I28) -> 0 | L28: =(E28+F28)*(H28+I28) -> 0 | M28: =C28*H28 -> 0 | N28: =D28*H28 -> 0 | O28: =E28*H28 -> 0 | P28: =F28*H28 -> 0 | Q28: =H28*G28*C28 -> 0 | R28: =I28*G28*C28 -> 0 | S28: =H28*G28*D28 -> 0 | T28: =I28*G28*D28 -> 0 | U28: =H28*G28*E28 -> 0 | V28: =I28*G28*E28 -> 0 | W28: =H28*G28*F28 -> 0 | X28: =I28*G28*F28 -> 0
A29: LA Kings | B29: 28 | C29: 0 | D29: 0 | E29: 0 | F29: 1 | G29: 134 | H29: 1 | I29: 0 | J29: =H29+I29 -> 1 | K29: =(C29+D29)*(H29+I29) -> 0 | L29: =(E29+F29)*(H29+I29) -> 1 | M29: =C29*H29 -> 0 | N29: =D29*H29 -> 0 | O29: =E29*H29 -> 0 | P29: =F29*H29 -> 1 | Q29: =H29*G29*C29 -> 0 | R29: =I29*G29*C29 -> 0 | S29: =H29*G29*D29 -> 0 | T29: =I29*G29*D29 -> 0 | U29: =H29*G29*E29 -> 0 | V29: =I29*G29*E29 -> 0 | W29: =H29*G29*F29 -> 134 | X29: =I29*G29*F29 -> 0
A30: San Jose Sharks | B30: 29 | C30: 0 | D30: 0 | E30: 0 | F30: 1 | G30: 148 | H30: 1 | I30: 0 | J30: =H30+I30 -> 1 | K30: =(C30+D30)*(H30+I30) -> 0 | L30: =(E30+F30)*(H30+I30) -> 1 | M30: =C30*H30 -> 0 | N30: =D30*H30 -> 0 | O30: =E30*H30 -> 0 | P30: =F30*H30 -> 1 | Q30: =H30*G30*C30 -> 0 | R30: =I30*G30*C30 -> 0 | S30: =H30*G30*D30 -> 0 | T30: =I30*G30*D30 -> 0 | U30: =H30*G30*E30 -> 0 | V30: =I30*G30*E30 -> 0 | W30: =H30*G30*F30 -> 148 | X30: =I30*G30*F30 -> 0
A31: Vancouver Canucks | B31: 30 | C31: 0 | D31: 0 | E31: 0 | F31: 1 | G31: 108 | H31: 0 | I31: 0 | J31: =H31+I31 -> 0 | K31: =(C31+D31)*(H31+I31) -> 0 | L31: =(E31+F31)*(H31+I31) -> 0 | M31: =C31*H31 -> 0 | N31: =D31*H31 -> 0 | O31: =E31*H31 -> 0 | P31: =F31*H31 -> 0 | Q31: =H31*G31*C31 -> 0 | R31: =I31*G31*C31 -> 0 | S31: =H31*G31*D31 -> 0 | T31: =I31*G31*D31 -> 0 | U31: =H31*G31*E31 -> 0 | V31: =I31*G31*E31 -> 0 | W31: =H31*G31*F31 -> 0 | X31: =I31*G31*F31 -> 0
A33: Sum (if applicable) | H33: =SUM(H2:H31) -> 12 | I33: =SUM(I2:I31) -> 4 | K33: =SUM(K2:K31) -> 8 | L33: =SUM(L2:L31) -> 8 | O33: Don’t change | V33: Metropolitan Division (EC)
O34: don’t change, decision variables det values | V34: Atlantic Division (EC)
O35: decision variables | V35: Central Division (WC)
O36: change (based on points/point system) | V36: Pacific Division (WC)
Q40: Points
Q41: from top division: | R41: =SUMPRODUCT(G2:G31,H2:H31) -> 1731
Q42: from wildcard: | R42: =SUMPRODUCT(G2:G31,I2:I31) -> 506
T43: Actual total points to playoff:
Q44: Maximize | R44: =2*R41+R42 -> 3968 | T44: =R41+R42 -> 2237 | X44: *Also, updated that we want to prioritize being on top of their division over having a wildcard spot, so 2*points in top position + 1*points in wildcard
...

Sheet 14.4
A1: Team | B1: i | C1: mi | D1: ai | E1: ci | F1: pi | G1: ti - current system | H1: d1i | I1: d2i | J1: d1i+d2i | K1: (ai+mi)*(d1i+d2i) | L1: (ci+pi)* (d1i+d2i) | M1: mi*d1i | N1: ai*d1i | O1: ci*d1i | P1: pi*d1i | Q1: d1i*ti*mi | R1: d2i*ti*mi | S1: d1i*ti*ai | T1: d2i*ti*ai | U1: d1i*ti*ci | V1: d2i*ti*ci | W1: d1i*ti*pi | X1: d2i*ti*pi
A2: Carolina Hurricanes | B2: 1 | C2: 1 | D2: 0 | E2: 0 | F2: 0 | G2: 83 | H2: 0 | I2: 0 | J2: =H2+I2 -> 0 | K2: =(C2+D2)*(H2+I2) -> 0 | L2: =(E2+F2)*(H2+I2) -> 0 | M2: =C2*H2 -> 0 | N2: =D2*H2 -> 0 | O2: =E2*H2 -> 0 | P2: =F2*H2 -> 0 | Q2: =H2*G2*C2 -> 0 | R2: =I2*G2*C2 -> 0 | S2: =H2*G2*D2 -> 0 | T2: =I2*G2*D2 -> 0 | U2: =H2*G2*E2 -> 0 | V2: =I2*G2*E2 -> 0 | W2: =H2*G2*F2 -> 0 | X2: =I2*G2*F2 -> 0
A3: Columbus Blue Jackets | B3: 2 | C3: 1 | D3: 0 | E3: 0 | F3: 0 | G3: 93 | H3: 1 | I3: 0 | J3: =H3+I3 -> 1 | K3: =(C3+D3)*(H3+I3) -> 1 | L3: =(E3+F3)*(H3+I3) -> 0 | M3: =C3*H3 -> 1 | N3: =D3*H3 -> 0 | O3: =E3*H3 -> 0 | P3: =F3*H3 -> 0 | Q3: =H3*G3*C3 -> 93 | R3: =I3*G3*C3 -> 0 | S3: =H3*G3*D3 -> 0 | T3: =I3*G3*D3 -> 0 | U3: =H3*G3*E3 -> 0 | V3: =I3*G3*E3 -> 0 | W3: =H3*G3*F3 -> 0 | X3: =I3*G3*F3 -> 0
A4: NJ Devils | B4: 3 | C4: 1 | D4: 0 | E4: 0 | F4: 0 | G4: 88 | H4: 0 | I4: 0 | J4: =H4+I4 -> 0 | K4: =(C4+D4)*(H4+I4) -> 0 | L4: =(E4+F4)*(H4+I4) -> 0 | M4: =C4*H4 -> 0 | N4: =D4*H4 -> 0 | O4: =E4*H4 -> 0 | P4: =F4*H4 -> 0 | Q4: =H4*G4*C4 -> 0 | R4: =I4*G4*C4 -> 0 | S4: =H4*G4*D4 -> 0 | T4: =I4*G4*D4 -> 0 | U4: =H4*G4*E4 -> 0 | V4: =I4*G4*E4 -> 0 | W4: =H4*G4*F4 -> 0 | X4: =I4*G4*F4 -> 0
A5: NY Islanders | B5: 4 | C5: 1 | D5: 0 | E5: 0 | F5: 0 | G5: 79 | H5: 0 | I5: 0 | J5: =H5+I5 -> 0 | K5: =(C5+D5)*(H5+I5) -> 0 | L5: =(E5+F5)*(H5+I5) -> 0 | M5: =C5*H5 -> 0 | N5: =D5*H5 -> 0 | O5: =E5*H5 -> 0 | P5: =F5*H5 -> 0 | Q5: =H5*G5*C5 -> 0 | R5: =I5*G5*C5 -> 0 | S5: =H5*G5*D5 -> 0 | T5: =I5*G5*D5 -> 0 | U5: =H5*G5*E5 -> 0 | V5: =I5*G5*E5 -> 0 | W5: =H5*G5*F5 -> 0 | X5: =I5*G5*F5 -> 0
A6: NY Rangers | B6: 5 | C6: 1 | D6: 0 | E6: 0 | F6: 0 | G6: 96 | H6: 1 | I6: 0 | J6: =H6+I6 -> 1 | K6: =(C6+D6)*(H6+I6) -> 1 | L6: =(E6+F6)*(H6+I6) -> 0 | M6: =C6*H6 -> 1 | N6: =D6*H6 -> 0 | O6: =E6*H6 -> 0 | P6: =F6*H6 -> 0 | Q6: =H6*G6*C6 -> 96 | R6: =I6*G6*C6 -> 0 | S6: =H6*G6*D6 -> 0 | T6: =I6*G6*D6 -> 0 | U6: =H6*G6*E6 -> 0 | V6: =I6*G6*E6 -> 0 | W6: =H6*G6*F6 -> 0 | X6: =I6*G6*F6 -> 0
A7: Philadelphia Flyers | B7: 6 | C7: 1 | D7: 0 | E7: 0 | F7: 0 | G7: 94 | H7: 1 | I7: 0 | J7: =H7+I7 -> 1 | K7: =(C7+D7)*(H7+I7) -> 1 | L7: =(E7+F7)*(H7+I7) -> 0 | M7: =C7*H7 -> 1 | N7: =D7*H7 -> 0 | O7: =E7*H7 -> 0 | P7: =F7*H7 -> 0 | Q7: =H7*G7*C7 -> 94 | R7: =I7*G7*C7 -> 0 | S7: =H7*G7*D7 -> 0 | T7: =I7*G7*D7 -> 0 | U7: =H7*G7*E7 -> 0 | V7: =I7*G7*E7 -> 0 | W7: =H7*G7*F7 -> 0 | X7: =I7*G7*F7 -> 0
A8: Pittsburg Penguins | B8: 7 | C8: 1 | D8: 0 | E8: 0 | F8: 0 | G8: 109 | H8: 1 | I8: 0 | J8: =H8+I8 -> 1 | K8: =(C8+D8)*(H8+I8) -> 1 | L8: =(E8+F8)*(H8+I8) -> 0 | M8: =C8*H8 -> 1 | N8: =D8*H8 -> 0 | O8: =E8*H8 -> 0 | P8: =F8*H8 -> 0 | Q8: =H8*G8*C8 -> 109 | R8: =I8*G8*C8 -> 0 | S8: =H8*G8*D8 -> 0 | T8: =I8*G8*D8 -> 0 | U8: =H8*G8*E8 -> 0 | V8: =I8*G8*E8 -> 0 | W8: =H8*G8*F8 -> 0 | X8: =I8*G8*F8 -> 0
A9: Washington Capitals | B9: 8 | C9: 1 | D9: 0 | E9: 0 | F9: 0 | G9: 90 | H9: 0 | I9: 0 | J9: =H9+I9 -> 0 | K9: =(C9+D9)*(H9+I9) -> 0 | L9: =(E9+F9)*(H9+I9) -> 0 | M9: =C9*H9 -> 0 | N9: =D9*H9 -> 0 | O9: =E9*H9 -> 0 | P9: =F9*H9 -> 0 | Q9: =H9*G9*C9 -> 0 | R9: =I9*G9*C9 -> 0 | S9: =H9*G9*D9 -> 0 | T9: =I9*G9*D9 -> 0 | U9: =H9*G9*E9 -> 0 | V9: =I9*G9*E9 -> 0 | W9: =H9*G9*F9 -> 0 | X9: =I9*G9*F9 -> 0
A10: Boston Bruins | B10: 9 | C10: 0 | D10: 1 | E10: 0 | F10: 0 | G10: 117 | H10: 1 | I10: 0 | J10: =H10+I10 -> 1 | K10: =(C10+D10)*(H10+I10) -> 1 | L10: =(E10+F10)*(H10+I10) -> 0 | M10: =C10*H10 -> 0 | N10: =D10*H10 -> 1 | O10: =E10*H10 -> 0 | P10: =F10*H10 -> 0 | Q10: =H10*G10*C10 -> 0 | R10: =I10*G10*C10 -> 0 | S10: =H10*G10*D10 -> 117 | T10: =I10*G10*D10 -> 0 | U10: =H10*G10*E10 -> 0 | V10: =I10*G10*E10 -> 0 | W10: =H10*G10*F10 -> 0 | X10: =I10*G10*F10 -> 0
A11: Buffalo Sabres | B11: 10 | C11: 0 | D11: 1 | E11: 0 | F11: 0 | G11: 52 | H11: 0 | I11: 0 | J11: =H11+I11 -> 0 | K11: =(C11+D11)*(H11+I11) -> 0 | L11: =(E11+F11)*(H11+I11) -> 0 | M11: =C11*H11 -> 0 | N11: =D11*H11 -> 0 | O11: =E11*H11 -> 0 | P11: =F11*H11 -> 0 | Q11: =H11*G11*C11 -> 0 | R11: =I11*G11*C11 -> 0 | S11: =H11*G11*D11 -> 0 | T11: =I11*G11*D11 -> 0 | U11: =H11*G11*E11 -> 0 | V11: =I11*G11*E11 -> 0 | W11: =H11*G11*F11 -> 0 | X11: =I11*G11*F11 -> 0
A12: Detroit Red Wings | B12: 11 | C12: 0 | D12: 1 | E12: 0 | F12: 0 | G12: 93 | H12: 1 | I12: 0 | J12: =H12+I12 -> 1 | K12: =(C12+D12)*(H12+I12) -> 1 | L12: =(E12+F12)*(H12+I12) -> 0 | M12: =C12*H12 -> 0 | N12: =D12*H12 -> 1 | O12: =E12*H12 -> 0 | P12: =F12*H12 -> 0 | Q12: =H12*G12*C12 -> 0 | R12: =I12*G12*C12 -> 0 | S12: =H12*G12*D12 -> 93 | T12: =I12*G12*D12 -> 0 | U12: =H12*G12*E12 -> 0 | V12: =I12*G12*E12 -> 0 | W12: =H12*G12*F12 -> 0 | X12: =I12*G12*F12 -> 0
A13: Florida Panthers | B13: 12 | C13: 0 | D13: 1 | E13: 0 | F13: 0 | G13: 66 | H13: 0 | I13: 0 | J13: =H13+I13 -> 0 | K13: =(C13+D13)*(H13+I13) -> 0 | L13: =(E13+F13)*(H13+I13) -> 0 | M13: =C13*H13 -> 0 | N13: =D13*H13 -> 0 | O13: =E13*H13 -> 0 | P13: =F13*H13 -> 0 | Q13: =H13*G13*C13 -> 0 | R13: =I13*G13*C13 -> 0 | S13: =H13*G13*D13 -> 0 | T13: =I13*G13*D13 -> 0 | U13: =H13*G13*E13 -> 0 | V13: =I13*G13*E13 -> 0 | W13: =H13*G13*F13 -> 0 | X13: =I13*G13*F13 -> 0
... A31: Vancouver Canucks | B31: 30 | C31: 0 | D31: 0 | E31: 0 | F31: 1 | G31: 83 | H31: 0 | I31: 0 | J31: =H31+I31 -> 0 | K31: =(C31+D31)*(H31+I31) -> 0 | L31: =(E31+F31)*(H31+I31) -> 0 | M31: =C31*H31 -> 0 | N31: =D31*H31 -> 0 | O31: =E31*H31 -> 0 | P31: =F31*H31 -> 0 | Q31: =H31*G31*C31 -> 0 | R31: =I31*G31*C31 -> 0 | S31: =H31*G31*D31 -> 0 | T31: =I31*G31*D31 -> 0 | U31: =H31*G31*E31 -> 0 | V31: =I31*G31*E31 -> 0 | W31: =H31*G31*F31 -> 0 | X31: =I31*G31*F31 -> 0
A33: Sum (if applicable) | H33: =SUM(H2:H31) -> 16 | I33: =SUM(I2:I31) -> 0 | K33: =SUM(K2:K31) -> 8 | L33: =SUM(L2:L31) -> 8 | O33: Don’t change | V33: Metropolitan Division (EC)
O34: don’t change, decision variables det values | V34: Atlantic Division (EC)
O35: decision variables | V35: Central Division (WC)
O36: change (based on points/point system) | V36: Pacific Division (WC)
Q40: Points
Q41: from top division: | R41: =SUMPRODUCT(G2:G31,H2:H31) -> 1647
Q42: from wildcard: | R42: =SUMPRODUCT(G2:G31,I2:I31) -> 0
T43: Actual total points to playoff:
Q44: Maximize | R44: =2*R41+R42 -> 3294 | T44: =R41+R42 -> 1647 | X44: *Also, updated that we want to prioritize being on top of their division over having a wildcard spot, so 2*points in top position + 1*points in wildcard
Q46: Subject to
R47: =SUM(H2:H31) +SUM(I2:I31) -> 16 | S47: .= | T47: 16
S48: <= | T48: 1
R49: =SUM(K2:K31) -> 8 | S49: <= | T49: 8
R50: =SUM(L2:L31) -> 8 | S50: <= | T50: 8
Q52: Eastern Conference | R52: =SUM(M2:M31) -> 4 | S52: .= | T52: =SUM(N2:N31) -> 4
Q53: Western Conference | R53: =SUM(O2:O31) -> 4 | S53: .= | T53: =SUM(P2:P31) -> 4
Q55: EC teams >= WC teams | R55: =R52 -> 4 | S55: >= | T55: =R53 -> 4
R56: This is to ensure EC have more teams than WC (this gets rid of the situation where WC > EC, making it unfair to EC teams in terms of points earned and guarantee of playoff spot)
Q58: Jen Added Constraints | R58: =SUMPRODUCT($H$2:$H$31,$C$2:$C$31) -> 4 | S58: <= | T58: 4 | U58: These constraints say that at most 4 teams from each division can make the playoff based on being top of their division.
R59: =SUMPRODUCT($H$2:$H$31,$D$2:$D$31) -> 4 | S59: <= | T59: 4
R60: =SUMPRODUCT($H$2:$H$31,$E$2:$E$31) -> 4 | S60: <= | T60: 4
R61: =SUMPRODUCT($H$2:$H$31,$F$2:$F$31) -> 4 | S61: <= | T61: 4
